[2025-02-06T18:29:47.440+0000] {local_task_job_runner.py:123} INFO - ::group::Pre task execution logs
[2025-02-06T18:29:47.449+0000] {taskinstance.py:2613} INFO - Dependencies all met for dep_context=non-requeueable deps ti=<TaskInstance: cluster_deployment.run_pre_check manual__2025-02-06T18:29:23.699474+00:00 [queued]>
[2025-02-06T18:29:47.453+0000] {taskinstance.py:2613} INFO - Dependencies all met for dep_context=requeueable deps ti=<TaskInstance: cluster_deployment.run_pre_check manual__2025-02-06T18:29:23.699474+00:00 [queued]>
[2025-02-06T18:29:47.454+0000] {taskinstance.py:2866} INFO - Starting attempt 1 of 2
[2025-02-06T18:29:47.460+0000] {taskinstance.py:2889} INFO - Executing <Task(PythonVirtualenvOperator): run_pre_check> on 2025-02-06 18:29:23.699474+00:00
[2025-02-06T18:29:47.464+0000] {warnings.py:112} WARNING - /home/***/.local/lib/python3.12/site-packages/***/task/task_runner/standard_task_runner.py:70: DeprecationWarning: This process (pid=2562) is multi-threaded, use of fork() may lead to deadlocks in the child.
  pid = os.fork()

[2025-02-06T18:29:47.465+0000] {standard_task_runner.py:72} INFO - Started process 2563 to run task
[2025-02-06T18:29:47.465+0000] {standard_task_runner.py:104} INFO - Running: ['***', 'tasks', 'run', 'cluster_deployment', 'run_pre_check', 'manual__2025-02-06T18:29:23.699474+00:00', '--job-id', '12', '--raw', '--subdir', 'DAGS_FOLDER/cluster_deployment.py', '--cfg-path', '/tmp/tmpan8gbdho']
[2025-02-06T18:29:47.466+0000] {standard_task_runner.py:105} INFO - Job 12: Subtask run_pre_check
[2025-02-06T18:29:47.494+0000] {task_command.py:467} INFO - Running <TaskInstance: cluster_deployment.run_pre_check manual__2025-02-06T18:29:23.699474+00:00 [running]> on host ***-worker
[2025-02-06T18:29:47.537+0000] {taskinstance.py:3132} INFO - Exporting env vars: AIRFLOW_CTX_DAG_OWNER='***' AIRFLOW_CTX_DAG_ID='cluster_deployment' AIRFLOW_CTX_TASK_ID='run_pre_check' AIRFLOW_CTX_EXECUTION_DATE='2025-02-06T18:29:23.699474+00:00' AIRFLOW_CTX_TRY_NUMBER='1' AIRFLOW_CTX_DAG_RUN_ID='manual__2025-02-06T18:29:23.699474+00:00'
[2025-02-06T18:29:47.538+0000] {logging_mixin.py:190} INFO - Task instance is in running state
[2025-02-06T18:29:47.538+0000] {logging_mixin.py:190} INFO -  Previous state of the Task instance: queued
[2025-02-06T18:29:47.538+0000] {logging_mixin.py:190} INFO - Current task name:run_pre_check state:running start_date:2025-02-06 18:29:47.449823+00:00
[2025-02-06T18:29:47.539+0000] {logging_mixin.py:190} INFO - Dag name:cluster_deployment and current dag run status:running
[2025-02-06T18:29:47.539+0000] {taskinstance.py:731} INFO - ::endgroup::
[2025-02-06T18:29:47.539+0000] {baseoperator.py:421} WARNING - PythonVirtualenvOperator.execute cannot be called outside TaskInstance!
[2025-02-06T18:29:47.540+0000] {process_utils.py:186} INFO - Executing cmd: /home/***/.local/bin/python -m virtualenv /tmp/venvyv_llni5 --system-site-packages --python=python
[2025-02-06T18:29:47.541+0000] {process_utils.py:190} INFO - Output:
[2025-02-06T18:29:48.047+0000] {process_utils.py:194} INFO - created virtual environment CPython3.12.8.final.0-64 in 125ms
[2025-02-06T18:29:48.047+0000] {process_utils.py:194} INFO -   creator CPython3Posix(dest=/tmp/venvyv_llni5, clear=False, no_vcs_ignore=False, global=True)
[2025-02-06T18:29:48.048+0000] {process_utils.py:194} INFO -   seeder FromAppData(download=False, pip=bundle, via=copy, app_data_dir=/home/***/.local/share/virtualenv)
[2025-02-06T18:29:48.049+0000] {process_utils.py:194} INFO -     added seed packages: pip==24.3.1
[2025-02-06T18:29:48.049+0000] {process_utils.py:194} INFO -   activators BashActivator,CShellActivator,FishActivator,NushellActivator,PowerShellActivator,PythonActivator
[2025-02-06T18:29:48.065+0000] {process_utils.py:186} INFO - Executing cmd: /tmp/venvyv_llni5/bin/pip install -r /tmp/venvyv_llni5/requirements.txt
[2025-02-06T18:29:48.066+0000] {process_utils.py:190} INFO - Output:
[2025-02-06T18:29:48.947+0000] {process_utils.py:194} INFO - Requirement already satisfied: pandas==2.1.4 in /home/***/.local/lib/python3.12/site-packages (from -r /tmp/venvyv_llni5/requirements.txt (line 1)) (2.1.4)
[2025-02-06T18:29:48.951+0000] {process_utils.py:194} INFO - Requirement already satisfied: numpy<2,>=1.26.0 in /home/***/.local/lib/python3.12/site-packages (from pandas==2.1.4->-r /tmp/venvyv_llni5/requirements.txt (line 1)) (1.26.4)
[2025-02-06T18:29:48.952+0000] {process_utils.py:194} INFO - Requirement already satisfied: python-dateutil>=2.8.2 in /home/***/.local/lib/python3.12/site-packages (from pandas==2.1.4->-r /tmp/venvyv_llni5/requirements.txt (line 1)) (2.9.0.post0)
[2025-02-06T18:29:48.952+0000] {process_utils.py:194} INFO - Requirement already satisfied: pytz>=2020.1 in /home/***/.local/lib/python3.12/site-packages (from pandas==2.1.4->-r /tmp/venvyv_llni5/requirements.txt (line 1)) (2024.2)
[2025-02-06T18:29:48.953+0000] {process_utils.py:194} INFO - Requirement already satisfied: tzdata>=2022.1 in /home/***/.local/lib/python3.12/site-packages (from pandas==2.1.4->-r /tmp/venvyv_llni5/requirements.txt (line 1)) (2024.2)
[2025-02-06T18:29:48.955+0000] {process_utils.py:194} INFO - Requirement already satisfied: six>=1.5 in /home/***/.local/lib/python3.12/site-packages (from python-dateutil>=2.8.2->pandas==2.1.4->-r /tmp/venvyv_llni5/requirements.txt (line 1)) (1.17.0)
[2025-02-06T18:29:49.329+0000] {process_utils.py:194} INFO - 
[2025-02-06T18:29:49.329+0000] {process_utils.py:194} INFO - [notice] A new release of pip is available: 24.3.1 -> 25.0
[2025-02-06T18:29:49.330+0000] {process_utils.py:194} INFO - [notice] To update, run: python -m pip install --upgrade pip
[2025-02-06T18:29:49.387+0000] {python.py:513} INFO - Use 'pickle' as serializer.
[2025-02-06T18:29:49.397+0000] {process_utils.py:186} INFO - Executing cmd: /tmp/venvyv_llni5/bin/python /tmp/venv-callvm50l041/script.py /tmp/venv-callvm50l041/script.in /tmp/venv-callvm50l041/script.out /tmp/venv-callvm50l041/string_args.txt /tmp/venv-callvm50l041/termination.log
[2025-02-06T18:29:49.398+0000] {process_utils.py:190} INFO - Output:
[2025-02-06T18:29:51.335+0000] {process_utils.py:194} INFO - [2025-02-06T18:29:51.334+0000] {script.py:23} INFO - Starting pre-deployment checks...
[2025-02-06T18:29:51.336+0000] {process_utils.py:194} INFO - [2025-02-06T18:29:51.335+0000] {script.py:32} INFO - Pre deployment report available:
[2025-02-06T18:29:51.336+0000] {process_utils.py:194} INFO - Traceback (most recent call last):
[2025-02-06T18:29:51.337+0000] {process_utils.py:194} INFO -   File "/tmp/venv-callvm50l041/script.py", line 82, in <module>
[2025-02-06T18:29:51.337+0000] {process_utils.py:194} INFO -     res = run_pre_check_fn(*arg_dict["args"], **arg_dict["kwargs"])
[2025-02-06T18:29:51.338+0000] {process_utils.py:194} INFO -           ^^^^^^^^^^^^^^^^^^^^^^^^^^^^^^^^^^^^^^^^^^^^^^^^^^^^^^^^^
[2025-02-06T18:29:51.338+0000] {process_utils.py:194} INFO -   File "/tmp/venv-callvm50l041/script.py", line 33, in run_pre_check_fn
[2025-02-06T18:29:51.338+0000] {process_utils.py:194} INFO -     logging.info(f"Ready? : {pre_deployment_checks_result['deployment_ready']}")
[2025-02-06T18:29:51.339+0000] {process_utils.py:194} INFO -                              ~~~~~~~~~~~~~~~~~~~~~~~~~~~~^^^^^^^^^^^^^^^^^^^^
[2025-02-06T18:29:51.339+0000] {process_utils.py:194} INFO - TypeError: string indices must be integers, not 'str'
[2025-02-06T18:29:51.708+0000] {taskinstance.py:3311} ERROR - Task failed with exception
Traceback (most recent call last):
  File "/home/airflow/.local/lib/python3.12/site-packages/airflow/models/taskinstance.py", line 767, in _execute_task
    result = _execute_callable(context=context, **execute_callable_kwargs)
             ^^^^^^^^^^^^^^^^^^^^^^^^^^^^^^^^^^^^^^^^^^^^^^^^^^^^^^^^^^^^^
  File "/home/airflow/.local/lib/python3.12/site-packages/airflow/models/taskinstance.py", line 733, in _execute_callable
    return ExecutionCallableRunner(
           ^^^^^^^^^^^^^^^^^^^^^^^^
  File "/home/airflow/.local/lib/python3.12/site-packages/airflow/utils/operator_helpers.py", line 252, in run
    return self.func(*args, **kwargs)
           ^^^^^^^^^^^^^^^^^^^^^^^^^^
  File "/home/airflow/.local/lib/python3.12/site-packages/airflow/models/baseoperator.py", line 422, in wrapper
    return func(self, *args, **kwargs)
           ^^^^^^^^^^^^^^^^^^^^^^^^^^^
  File "/home/airflow/.local/lib/python3.12/site-packages/airflow/operators/python.py", line 505, in execute
    return super().execute(context=serializable_context)
           ^^^^^^^^^^^^^^^^^^^^^^^^^^^^^^^^^^^^^^^^^^^^^
  File "/home/airflow/.local/lib/python3.12/site-packages/airflow/models/baseoperator.py", line 422, in wrapper
    return func(self, *args, **kwargs)
           ^^^^^^^^^^^^^^^^^^^^^^^^^^^
  File "/home/airflow/.local/lib/python3.12/site-packages/airflow/operators/python.py", line 238, in execute
    return_value = self.execute_callable()
                   ^^^^^^^^^^^^^^^^^^^^^^^
  File "/home/airflow/.local/lib/python3.12/site-packages/airflow/operators/python.py", line 870, in execute_callable
    result = self._execute_python_callable_in_subprocess(python_path)
             ^^^^^^^^^^^^^^^^^^^^^^^^^^^^^^^^^^^^^^^^^^^^^^^^^^^^^^^^
  File "/home/airflow/.local/lib/python3.12/site-packages/airflow/operators/python.py", line 588, in _execute_python_callable_in_subprocess
    raise AirflowException(error_msg) from None
airflow.exceptions.AirflowException: Process returned non-zero exit status 1.
string indices must be integers, not 'str'
[2025-02-06T18:29:51.715+0000] {logging_mixin.py:190} INFO - Task instance in failure state
[2025-02-06T18:29:51.716+0000] {logging_mixin.py:190} INFO - Task start:2025-02-06 18:29:47.449823+00:00 end:2025-02-06 18:29:51.714965+00:00 duration:4.265142
[2025-02-06T18:29:51.716+0000] {logging_mixin.py:190} INFO - Task:<Task(PythonVirtualenvOperator): run_pre_check> dag:<DAG: cluster_deployment> dagrun:<DagRun cluster_deployment @ 2025-02-06 18:29:23.699474+00:00: manual__2025-02-06T18:29:23.699474+00:00, state:running, queued_at: 2025-02-06 18:29:23.717079+00:00. externally triggered: True>
[2025-02-06T18:29:51.716+0000] {logging_mixin.py:190} INFO - Failure caused by Process returned non-zero exit status 1.
string indices must be integers, not 'str'
[2025-02-06T18:29:51.716+0000] {taskinstance.py:1225} INFO - Marking task as UP_FOR_RETRY. dag_id=cluster_deployment, task_id=run_pre_check, run_id=manual__2025-02-06T18:29:23.699474+00:00, execution_date=20250206T182923, start_date=20250206T182947, end_date=20250206T182951
[2025-02-06T18:29:51.729+0000] {taskinstance.py:340} INFO - ::group::Post task execution logs
[2025-02-06T18:29:51.729+0000] {standard_task_runner.py:124} ERROR - Failed to execute job 12 for task run_pre_check (Process returned non-zero exit status 1.
string indices must be integers, not 'str'; 2563)
Traceback (most recent call last):
  File "/home/airflow/.local/lib/python3.12/site-packages/airflow/task/task_runner/standard_task_runner.py", line 117, in _start_by_fork
    ret = args.func(args, dag=self.dag)
          ^^^^^^^^^^^^^^^^^^^^^^^^^^^^^
  File "/home/airflow/.local/lib/python3.12/site-packages/airflow/cli/cli_config.py", line 49, in command
    return func(*args, **kwargs)
           ^^^^^^^^^^^^^^^^^^^^^
  File "/home/airflow/.local/lib/python3.12/site-packages/airflow/utils/cli.py", line 116, in wrapper
    return f(*args, **kwargs)
           ^^^^^^^^^^^^^^^^^^
  File "/home/airflow/.local/lib/python3.12/site-packages/airflow/cli/commands/task_command.py", line 483, in task_run
    task_return_code = _run_task_by_selected_method(args, _dag, ti)
                       ^^^^^^^^^^^^^^^^^^^^^^^^^^^^^^^^^^^^^^^^^^^^
  File "/home/airflow/.local/lib/python3.12/site-packages/airflow/cli/commands/task_command.py", line 256, in _run_task_by_selected_method
    return _run_raw_task(args, ti)
           ^^^^^^^^^^^^^^^^^^^^^^^
  File "/home/airflow/.local/lib/python3.12/site-packages/airflow/cli/commands/task_command.py", line 341, in _run_raw_task
    return ti._run_raw_task(
           ^^^^^^^^^^^^^^^^^
  File "/home/airflow/.local/lib/python3.12/site-packages/airflow/utils/session.py", line 97, in wrapper
    return func(*args, session=session, **kwargs)
           ^^^^^^^^^^^^^^^^^^^^^^^^^^^^^^^^^^^^^^
  File "/home/airflow/.local/lib/python3.12/site-packages/airflow/models/taskinstance.py", line 3005, in _run_raw_task
    return _run_raw_task(
           ^^^^^^^^^^^^^^
  File "/home/airflow/.local/lib/python3.12/site-packages/airflow/models/taskinstance.py", line 273, in _run_raw_task
    TaskInstance._execute_task_with_callbacks(
  File "/home/airflow/.local/lib/python3.12/site-packages/airflow/models/taskinstance.py", line 3159, in _execute_task_with_callbacks
    result = self._execute_task(context, task_orig)
             ^^^^^^^^^^^^^^^^^^^^^^^^^^^^^^^^^^^^^^
  File "/home/airflow/.local/lib/python3.12/site-packages/airflow/models/taskinstance.py", line 3183, in _execute_task
    return _execute_task(self, context, task_orig)
           ^^^^^^^^^^^^^^^^^^^^^^^^^^^^^^^^^^^^^^^
  File "/home/airflow/.local/lib/python3.12/site-packages/airflow/models/taskinstance.py", line 767, in _execute_task
    result = _execute_callable(context=context, **execute_callable_kwargs)
             ^^^^^^^^^^^^^^^^^^^^^^^^^^^^^^^^^^^^^^^^^^^^^^^^^^^^^^^^^^^^^
  File "/home/airflow/.local/lib/python3.12/site-packages/airflow/models/taskinstance.py", line 733, in _execute_callable
    return ExecutionCallableRunner(
           ^^^^^^^^^^^^^^^^^^^^^^^^
  File "/home/airflow/.local/lib/python3.12/site-packages/airflow/utils/operator_helpers.py", line 252, in run
    return self.func(*args, **kwargs)
           ^^^^^^^^^^^^^^^^^^^^^^^^^^
  File "/home/airflow/.local/lib/python3.12/site-packages/airflow/models/baseoperator.py", line 422, in wrapper
    return func(self, *args, **kwargs)
           ^^^^^^^^^^^^^^^^^^^^^^^^^^^
  File "/home/airflow/.local/lib/python3.12/site-packages/airflow/operators/python.py", line 505, in execute
    return super().execute(context=serializable_context)
           ^^^^^^^^^^^^^^^^^^^^^^^^^^^^^^^^^^^^^^^^^^^^^
  File "/home/airflow/.local/lib/python3.12/site-packages/airflow/models/baseoperator.py", line 422, in wrapper
    return func(self, *args, **kwargs)
           ^^^^^^^^^^^^^^^^^^^^^^^^^^^
  File "/home/airflow/.local/lib/python3.12/site-packages/airflow/operators/python.py", line 238, in execute
    return_value = self.execute_callable()
                   ^^^^^^^^^^^^^^^^^^^^^^^
  File "/home/airflow/.local/lib/python3.12/site-packages/airflow/operators/python.py", line 870, in execute_callable
    result = self._execute_python_callable_in_subprocess(python_path)
             ^^^^^^^^^^^^^^^^^^^^^^^^^^^^^^^^^^^^^^^^^^^^^^^^^^^^^^^^
  File "/home/airflow/.local/lib/python3.12/site-packages/airflow/operators/python.py", line 588, in _execute_python_callable_in_subprocess
    raise AirflowException(error_msg) from None
airflow.exceptions.AirflowException: Process returned non-zero exit status 1.
string indices must be integers, not 'str'
[2025-02-06T18:29:51.776+0000] {local_task_job_runner.py:266} INFO - Task exited with return code 1
[2025-02-06T18:29:51.796+0000] {taskinstance.py:3895} INFO - 0 downstream tasks scheduled from follow-on schedule check
[2025-02-06T18:29:51.798+0000] {local_task_job_runner.py:245} INFO - ::endgroup::
