[2025-02-05T12:54:46.884+0000] {local_task_job_runner.py:123} INFO - ::group::Pre task execution logs
[2025-02-05T12:54:46.894+0000] {taskinstance.py:2613} INFO - Dependencies all met for dep_context=non-requeueable deps ti=<TaskInstance: external_signal_workflow.task_1 manual__2025-02-05T12:54:44.770023+00:00 [queued]>
[2025-02-05T12:54:46.899+0000] {taskinstance.py:2613} INFO - Dependencies all met for dep_context=requeueable deps ti=<TaskInstance: external_signal_workflow.task_1 manual__2025-02-05T12:54:44.770023+00:00 [queued]>
[2025-02-05T12:54:46.899+0000] {taskinstance.py:2866} INFO - Starting attempt 1 of 2
[2025-02-05T12:54:46.907+0000] {taskinstance.py:2889} INFO - Executing <Task(PythonVirtualenvOperator): task_1> on 2025-02-05 12:54:44.770023+00:00
[2025-02-05T12:54:46.912+0000] {warnings.py:112} WARNING - /home/***/.local/lib/python3.12/site-packages/***/task/task_runner/standard_task_runner.py:70: DeprecationWarning: This process (pid=592) is multi-threaded, use of fork() may lead to deadlocks in the child.
  pid = os.fork()

[2025-02-05T12:54:46.913+0000] {standard_task_runner.py:72} INFO - Started process 593 to run task
[2025-02-05T12:54:46.914+0000] {standard_task_runner.py:104} INFO - Running: ['***', 'tasks', 'run', 'external_signal_workflow', 'task_1', 'manual__2025-02-05T12:54:44.770023+00:00', '--job-id', '19', '--raw', '--subdir', 'DAGS_FOLDER/external_signal_workflow.py', '--cfg-path', '/tmp/tmpgt1tly2z']
[2025-02-05T12:54:46.915+0000] {standard_task_runner.py:105} INFO - Job 19: Subtask task_1
[2025-02-05T12:54:47.247+0000] {task_command.py:467} INFO - Running <TaskInstance: external_signal_workflow.task_1 manual__2025-02-05T12:54:44.770023+00:00 [running]> on host ***-worker-3
[2025-02-05T12:54:47.285+0000] {taskinstance.py:3132} INFO - Exporting env vars: AIRFLOW_CTX_DAG_OWNER='***' AIRFLOW_CTX_DAG_ID='external_signal_workflow' AIRFLOW_CTX_TASK_ID='task_1' AIRFLOW_CTX_EXECUTION_DATE='2025-02-05T12:54:44.770023+00:00' AIRFLOW_CTX_TRY_NUMBER='1' AIRFLOW_CTX_DAG_RUN_ID='manual__2025-02-05T12:54:44.770023+00:00'
[2025-02-05T12:54:47.286+0000] {logging_mixin.py:190} INFO - Task instance is in running state
[2025-02-05T12:54:47.286+0000] {logging_mixin.py:190} INFO -  Previous state of the Task instance: queued
[2025-02-05T12:54:47.287+0000] {logging_mixin.py:190} INFO - Current task name:task_1 state:running start_date:2025-02-05 12:54:46.894950+00:00
[2025-02-05T12:54:47.287+0000] {logging_mixin.py:190} INFO - Dag name:external_signal_workflow and current dag run status:running
[2025-02-05T12:54:47.287+0000] {taskinstance.py:731} INFO - ::endgroup::
[2025-02-05T12:54:47.287+0000] {baseoperator.py:421} WARNING - PythonVirtualenvOperator.execute cannot be called outside TaskInstance!
[2025-02-05T12:54:47.288+0000] {process_utils.py:186} INFO - Executing cmd: /home/***/.local/bin/python -m virtualenv /tmp/venv8ukqsvdz --system-site-packages --python=python
[2025-02-05T12:54:47.289+0000] {process_utils.py:190} INFO - Output:
[2025-02-05T12:54:47.894+0000] {process_utils.py:194} INFO - created virtual environment CPython3.12.8.final.0-64 in 206ms
[2025-02-05T12:54:47.895+0000] {process_utils.py:194} INFO -   creator CPython3Posix(dest=/tmp/venv8ukqsvdz, clear=False, no_vcs_ignore=False, global=True)
[2025-02-05T12:54:47.895+0000] {process_utils.py:194} INFO -   seeder FromAppData(download=False, pip=bundle, via=copy, app_data_dir=/home/***/.local/share/virtualenv)
[2025-02-05T12:54:47.896+0000] {process_utils.py:194} INFO -     added seed packages: pip==24.3.1
[2025-02-05T12:54:47.896+0000] {process_utils.py:194} INFO -   activators BashActivator,CShellActivator,FishActivator,NushellActivator,PowerShellActivator,PythonActivator
[2025-02-05T12:54:47.913+0000] {process_utils.py:186} INFO - Executing cmd: /tmp/venv8ukqsvdz/bin/pip install -r /tmp/venv8ukqsvdz/requirements.txt
[2025-02-05T12:54:47.914+0000] {process_utils.py:190} INFO - Output:
[2025-02-05T12:54:48.975+0000] {process_utils.py:194} INFO - ERROR: Could not find a version that satisfies the requirement pandas==2.3.3 (from versions: 2.1.1, 2.1.2, 2.1.3, 2.1.4, 2.2.0rc0, 2.2.0, 2.2.1, 2.2.2, 2.2.3)
[2025-02-05T12:54:49.152+0000] {process_utils.py:194} INFO - 
[2025-02-05T12:54:49.152+0000] {process_utils.py:194} INFO - [notice] A new release of pip is available: 24.3.1 -> 25.0
[2025-02-05T12:54:49.152+0000] {process_utils.py:194} INFO - [notice] To update, run: python -m pip install --upgrade pip
[2025-02-05T12:54:49.152+0000] {process_utils.py:194} INFO - ERROR: No matching distribution found for pandas==2.3.3
[2025-02-05T12:54:49.209+0000] {taskinstance.py:3311} ERROR - Task failed with exception
Traceback (most recent call last):
  File "/home/airflow/.local/lib/python3.12/site-packages/airflow/models/taskinstance.py", line 767, in _execute_task
    result = _execute_callable(context=context, **execute_callable_kwargs)
             ^^^^^^^^^^^^^^^^^^^^^^^^^^^^^^^^^^^^^^^^^^^^^^^^^^^^^^^^^^^^^
  File "/home/airflow/.local/lib/python3.12/site-packages/airflow/models/taskinstance.py", line 733, in _execute_callable
    return ExecutionCallableRunner(
           ^^^^^^^^^^^^^^^^^^^^^^^^
  File "/home/airflow/.local/lib/python3.12/site-packages/airflow/utils/operator_helpers.py", line 252, in run
    return self.func(*args, **kwargs)
           ^^^^^^^^^^^^^^^^^^^^^^^^^^
  File "/home/airflow/.local/lib/python3.12/site-packages/airflow/models/baseoperator.py", line 422, in wrapper
    return func(self, *args, **kwargs)
           ^^^^^^^^^^^^^^^^^^^^^^^^^^^
  File "/home/airflow/.local/lib/python3.12/site-packages/airflow/operators/python.py", line 505, in execute
    return super().execute(context=serializable_context)
           ^^^^^^^^^^^^^^^^^^^^^^^^^^^^^^^^^^^^^^^^^^^^^
  File "/home/airflow/.local/lib/python3.12/site-packages/airflow/models/baseoperator.py", line 422, in wrapper
    return func(self, *args, **kwargs)
           ^^^^^^^^^^^^^^^^^^^^^^^^^^^
  File "/home/airflow/.local/lib/python3.12/site-packages/airflow/operators/python.py", line 238, in execute
    return_value = self.execute_callable()
                   ^^^^^^^^^^^^^^^^^^^^^^^
  File "/home/airflow/.local/lib/python3.12/site-packages/airflow/operators/python.py", line 868, in execute_callable
    self._prepare_venv(tmp_path)
  File "/home/airflow/.local/lib/python3.12/site-packages/airflow/operators/python.py", line 769, in _prepare_venv
    prepare_virtualenv(
  File "/home/airflow/.local/lib/python3.12/site-packages/airflow/utils/python_virtualenv.py", line 119, in prepare_virtualenv
    execute_in_subprocess(pip_cmd)
  File "/home/airflow/.local/lib/python3.12/site-packages/airflow/utils/process_utils.py", line 175, in execute_in_subprocess
    execute_in_subprocess_with_kwargs(cmd, cwd=cwd, env=env)
  File "/home/airflow/.local/lib/python3.12/site-packages/airflow/utils/process_utils.py", line 198, in execute_in_subprocess_with_kwargs
    raise subprocess.CalledProcessError(exit_code, cmd)
subprocess.CalledProcessError: Command '['/tmp/venv8ukqsvdz/bin/pip', 'install', '-r', '/tmp/venv8ukqsvdz/requirements.txt']' returned non-zero exit status 1.
[2025-02-05T12:54:49.216+0000] {logging_mixin.py:190} INFO - Task instance in failure state
[2025-02-05T12:54:49.217+0000] {logging_mixin.py:190} INFO - Task start:2025-02-05 12:54:46.894950+00:00 end:2025-02-05 12:54:49.216782+00:00 duration:2.321832
[2025-02-05T12:54:49.217+0000] {logging_mixin.py:190} INFO - Task:<Task(PythonVirtualenvOperator): task_1> dag:<DAG: external_signal_workflow> dagrun:<DagRun external_signal_workflow @ 2025-02-05 12:54:44.770023+00:00: manual__2025-02-05T12:54:44.770023+00:00, state:running, queued_at: 2025-02-05 12:54:44.794443+00:00. externally triggered: True>
[2025-02-05T12:54:49.217+0000] {logging_mixin.py:190} INFO - Failure caused by Command '['/tmp/venv8ukqsvdz/bin/pip', 'install', '-r', '/tmp/venv8ukqsvdz/requirements.txt']' returned non-zero exit status 1.
[2025-02-05T12:54:49.218+0000] {taskinstance.py:1225} INFO - Marking task as UP_FOR_RETRY. dag_id=external_signal_workflow, task_id=task_1, run_id=manual__2025-02-05T12:54:44.770023+00:00, execution_date=20250205T125444, start_date=20250205T125446, end_date=20250205T125449
[2025-02-05T12:54:49.226+0000] {taskinstance.py:340} INFO - ::group::Post task execution logs
[2025-02-05T12:54:49.226+0000] {standard_task_runner.py:124} ERROR - Failed to execute job 19 for task task_1 (Command '['/tmp/venv8ukqsvdz/bin/pip', 'install', '-r', '/tmp/venv8ukqsvdz/requirements.txt']' returned non-zero exit status 1.; 593)
Traceback (most recent call last):
  File "/home/airflow/.local/lib/python3.12/site-packages/airflow/task/task_runner/standard_task_runner.py", line 117, in _start_by_fork
    ret = args.func(args, dag=self.dag)
          ^^^^^^^^^^^^^^^^^^^^^^^^^^^^^
  File "/home/airflow/.local/lib/python3.12/site-packages/airflow/cli/cli_config.py", line 49, in command
    return func(*args, **kwargs)
           ^^^^^^^^^^^^^^^^^^^^^
  File "/home/airflow/.local/lib/python3.12/site-packages/airflow/utils/cli.py", line 116, in wrapper
    return f(*args, **kwargs)
           ^^^^^^^^^^^^^^^^^^
  File "/home/airflow/.local/lib/python3.12/site-packages/airflow/cli/commands/task_command.py", line 483, in task_run
    task_return_code = _run_task_by_selected_method(args, _dag, ti)
                       ^^^^^^^^^^^^^^^^^^^^^^^^^^^^^^^^^^^^^^^^^^^^
  File "/home/airflow/.local/lib/python3.12/site-packages/airflow/cli/commands/task_command.py", line 256, in _run_task_by_selected_method
    return _run_raw_task(args, ti)
           ^^^^^^^^^^^^^^^^^^^^^^^
  File "/home/airflow/.local/lib/python3.12/site-packages/airflow/cli/commands/task_command.py", line 341, in _run_raw_task
    return ti._run_raw_task(
           ^^^^^^^^^^^^^^^^^
  File "/home/airflow/.local/lib/python3.12/site-packages/airflow/utils/session.py", line 97, in wrapper
    return func(*args, session=session, **kwargs)
           ^^^^^^^^^^^^^^^^^^^^^^^^^^^^^^^^^^^^^^
  File "/home/airflow/.local/lib/python3.12/site-packages/airflow/models/taskinstance.py", line 3005, in _run_raw_task
    return _run_raw_task(
           ^^^^^^^^^^^^^^
  File "/home/airflow/.local/lib/python3.12/site-packages/airflow/models/taskinstance.py", line 273, in _run_raw_task
    TaskInstance._execute_task_with_callbacks(
  File "/home/airflow/.local/lib/python3.12/site-packages/airflow/models/taskinstance.py", line 3159, in _execute_task_with_callbacks
    result = self._execute_task(context, task_orig)
             ^^^^^^^^^^^^^^^^^^^^^^^^^^^^^^^^^^^^^^
  File "/home/airflow/.local/lib/python3.12/site-packages/airflow/models/taskinstance.py", line 3183, in _execute_task
    return _execute_task(self, context, task_orig)
           ^^^^^^^^^^^^^^^^^^^^^^^^^^^^^^^^^^^^^^^
  File "/home/airflow/.local/lib/python3.12/site-packages/airflow/models/taskinstance.py", line 767, in _execute_task
    result = _execute_callable(context=context, **execute_callable_kwargs)
             ^^^^^^^^^^^^^^^^^^^^^^^^^^^^^^^^^^^^^^^^^^^^^^^^^^^^^^^^^^^^^
  File "/home/airflow/.local/lib/python3.12/site-packages/airflow/models/taskinstance.py", line 733, in _execute_callable
    return ExecutionCallableRunner(
           ^^^^^^^^^^^^^^^^^^^^^^^^
  File "/home/airflow/.local/lib/python3.12/site-packages/airflow/utils/operator_helpers.py", line 252, in run
    return self.func(*args, **kwargs)
           ^^^^^^^^^^^^^^^^^^^^^^^^^^
  File "/home/airflow/.local/lib/python3.12/site-packages/airflow/models/baseoperator.py", line 422, in wrapper
    return func(self, *args, **kwargs)
           ^^^^^^^^^^^^^^^^^^^^^^^^^^^
  File "/home/airflow/.local/lib/python3.12/site-packages/airflow/operators/python.py", line 505, in execute
    return super().execute(context=serializable_context)
           ^^^^^^^^^^^^^^^^^^^^^^^^^^^^^^^^^^^^^^^^^^^^^
  File "/home/airflow/.local/lib/python3.12/site-packages/airflow/models/baseoperator.py", line 422, in wrapper
    return func(self, *args, **kwargs)
           ^^^^^^^^^^^^^^^^^^^^^^^^^^^
  File "/home/airflow/.local/lib/python3.12/site-packages/airflow/operators/python.py", line 238, in execute
    return_value = self.execute_callable()
                   ^^^^^^^^^^^^^^^^^^^^^^^
  File "/home/airflow/.local/lib/python3.12/site-packages/airflow/operators/python.py", line 868, in execute_callable
    self._prepare_venv(tmp_path)
  File "/home/airflow/.local/lib/python3.12/site-packages/airflow/operators/python.py", line 769, in _prepare_venv
    prepare_virtualenv(
  File "/home/airflow/.local/lib/python3.12/site-packages/airflow/utils/python_virtualenv.py", line 119, in prepare_virtualenv
    execute_in_subprocess(pip_cmd)
  File "/home/airflow/.local/lib/python3.12/site-packages/airflow/utils/process_utils.py", line 175, in execute_in_subprocess
    execute_in_subprocess_with_kwargs(cmd, cwd=cwd, env=env)
  File "/home/airflow/.local/lib/python3.12/site-packages/airflow/utils/process_utils.py", line 198, in execute_in_subprocess_with_kwargs
    raise subprocess.CalledProcessError(exit_code, cmd)
subprocess.CalledProcessError: Command '['/tmp/venv8ukqsvdz/bin/pip', 'install', '-r', '/tmp/venv8ukqsvdz/requirements.txt']' returned non-zero exit status 1.
[2025-02-05T12:54:49.269+0000] {local_task_job_runner.py:266} INFO - Task exited with return code 1
[2025-02-05T12:54:49.403+0000] {taskinstance.py:3895} INFO - 0 downstream tasks scheduled from follow-on schedule check
[2025-02-05T12:54:49.404+0000] {local_task_job_runner.py:245} INFO - ::endgroup::
